<div class="container">
  <app-header title="catchError()" category="Operators" subtitle="Formerly known as <code>catch()</code>"></app-header>

  <app-documentation link="https://rxjs.dev/api/operators/catchError"
                     marble="http://reactivex.io/documentation/operators/images/catch.js.png">
    <p>
      Gracefully handle errors in an observable sequence.
    </p>
    <p>
      Remember to return an observable from the catchError function!
    </p>
  </app-documentation>

  <app-signature>
    <pre class="my-0"><code class="language-ts">
      catchError&lt;T&gt;(selector: (err: any, caught: Observable&lt;T&gt;) =&gt; never): MonoTypeOperatorFunction&lt;T&gt;;
      catchError&lt;T, R&gt;(selector: (err: any, caught: Observable&lt;T&gt;) =&gt; ObservableInput&lt;R&gt;): OperatorFunction&lt;T, T | R&gt;;
    </code></pre>
  </app-signature>

  <app-example-code>
    <pre class="my-0 line-numbers"><code class="language-ts">
      import &#123; of &#125; from 'rxjs';
      import &#123; catchError, map &#125; from 'rxjs/operators';

      of(1, 2, 3, 4, 5)
      .pipe(
        map((value: number) =>  &#123;
          if (value === 4)  &#123;
            throw new Error('four!');
           &#125;
      
          return value;
         &#125;),
        catchError((error: any) =>  &#123;
          console.error('Error caught:', error.message);
          return of('I', 'II', 'III', 'IV', 'V');
         &#125;)
      );
      .subscribe((value: number | string) => console.log(value));

      // Output: 1
      // Output: 2
      // Output: 3
      // [Console]: Error caught: four!
      // Output: 'I'
      // Output: 'II'
      // Output: 'III'
      // Output: 'IV'
      // Output: 'V'
    </code></pre>
  </app-example-code>

  <app-results [results]="results" [isRunning]="isRunning" (onStop)="stop()" (onStart)="start()"></app-results>
</div>
